Workbook

Sheet Mesas
A1: MESAS DE TRABAJO POLITICA PÚBLICA DE SEGURIDAD HUMANA INTEGRAL
A2: Mesas | C2: Dirección | D2: Fecha | E2: Hora | F2: Dimensión principal (seguridad humana) | G2: Otras dimensiones | H2: Eje transversal Crisis (N° actores) | I2: Total actores | J2: Principales | K2: Secundarios | L2: Actores clave (principales) | M2: Meta de personas | N2: % de la meta total | O2: Meta máxima (+500)
A3: Mesas Territoriales | B3: Localidad Histórica y del Caribe Norte | C3: Por definir | D3: Por definir | E3: Por definir | F3: Comunitaria | G3: Personal; Económica | H3: =COUNTIFS('Detalle por mesa'!$B:$B,$B3,'Detalle por mesa'!$I:$I,"Principal")+COUNTIFS('Detalle por mesa'!$B:$B,$B3,'Detalle por mesa'!$I:$I,"Secundario") -> 3 | I3: =COUNTIF('Detalle por mesa'!$B:$B,$B3) -> 19 | J3: =COUNTIFS('Detalle por mesa'!$B:$B,$B3,'Detalle por mesa'!$G:$G,"Principal") -> 9 | K3: =COUNTIFS('Detalle por mesa'!$B:$B,$B3,'Detalle por mesa'!$G:$G,"Secundario") -> 10 | L3: Alcaldías Locales 1, 2 y 3; Instituto Distrital de Acción Comunal (IDACC); Instituto de Patrimonio y Cultura de Cartagena (IPCC); Secretaría de Participación y Desarrollo Social (SPD/UMATA) (+5 más; ver hoja Detalle) | M3: 350 | N3: =M3/$M$42 -> 0.14 | O3: ='Proyección ±500'!F24 -> 420
B4: Localidad De La Virgen y Turística | C4: Por definir | D4: Por definir | E4: Por definir | F4: Comunitaria | G4: Económica; Personal | H4: =COUNTIFS('Detalle por mesa'!$B:$B,$B4,'Detalle por mesa'!$I:$I,"Principal")+COUNTIFS('Detalle por mesa'!$B:$B,$B4,'Detalle por mesa'!$I:$I,"Secundario") -> 3 | I4: =COUNTIF('Detalle por mesa'!$B:$B,$B4) -> 18 | J4: =COUNTIFS('Detalle por mesa'!$B:$B,$B4,'Detalle por mesa'!$G:$G,"Principal") -> 7 | K4: =COUNTIFS('Detalle por mesa'!$B:$B,$B4,'Detalle por mesa'!$G:$G,"Secundario") -> 11 | L4: Alcaldías Locales 1, 2 y 3; Instituto Distrital de Acción Comunal (IDACC); Secretaría de Participación y Desarrollo Social (SPD/UMATA); Secretaría de Turismo (+3 más; ver hoja Detalle) | M4: 400 | N4: =M4/$M$42 -> 0.16 | O4: ='Proyección ±500'!F25 -> 480
B5: Localidad Industrial y de la Bahía | C5: Por definir | D5: Por definir | E5: Por definir | F5: Comunitaria | G5: Económica; Personal | H5: =COUNTIFS('Detalle por mesa'!$B:$B,$B5,'Detalle por mesa'!$I:$I,"Principal")+COUNTIFS('Detalle por mesa'!$B:$B,$B5,'Detalle por mesa'!$I:$I,"Secundario") -> 3 | I5: =COUNTIF('Detalle por mesa'!$B:$B,$B5) -> 17 | J5: =COUNTIFS('Detalle por mesa'!$B:$B,$B5,'Detalle por mesa'!$G:$G,"Principal") -> 7 | K5: =COUNTIFS('Detalle por mesa'!$B:$B,$B5,'Detalle por mesa'!$G:$G,"Secundario") -> 10 | L5: Alcaldías Locales 1, 2 y 3; Instituto Distrital de Acción Comunal (IDACC); Secretaría de Participación y Desarrollo Social (SPD/UMATA); Asociaciones de Juntas de Acción Comunal (ASOJAC) (+3 más; ver hoja Detalle) | M5: 350 | N5: =M5/$M$42 -> 0.14 | O5: ='Proyección ±500'!F26 -> 420
A7: Mesas Rurales | B7: Boquilla | C7: Por definir | D7: Por definir | E7: Por definir | F7: Comunitaria | G7: Ambiental | H7: =COUNTIFS('Detalle por mesa'!$B:$B,$B7,'Detalle por mesa'!$I:$I,"Principal")+COUNTIFS('Detalle por mesa'!$B:$B,$B7,'Detalle por mesa'!$I:$I,"Secundario") -> 4 | I7: =COUNTIF('Detalle por mesa'!$B:$B,$B7) -> 12 | J7: =COUNTIFS('Detalle por mesa'!$B:$B,$B7,'Detalle por mesa'!$G:$G,"Principal") -> 5 | K7: =COUNTIFS('Detalle por mesa'!$B:$B,$B7,'Detalle por mesa'!$G:$G,"Secundario") -> 7 | L7: Alcaldías Locales 1, 2 y 3; Instituto Distrital de Acción Comunal (IDACC); Secretaría de Participación y Desarrollo Social (SPD/UMATA); Asociaciones de Juntas de Acción Comunal (ASOJAC) (+1 más; ver hoja Detalle) | M7: 60 | N7: =M7/$M$42 -> 0.024 | O7: ='Proyección ±500'!F29 -> 75
B8: Arroyo de Piedra | C8: Por definir | D8: Por definir | E8: Por definir | F8: Comunitaria | G8: Ambiental | H8: =COUNTIFS('Detalle por mesa'!$B:$B,$B8,'Detalle por mesa'!$I:$I,"Principal")+COUNTIFS('Detalle por mesa'!$B:$B,$B8,'Detalle por mesa'!$I:$I,"Secundario") -> 4 | I8: =COUNTIF('Detalle por mesa'!$B:$B,$B8) -> 12 | J8: =COUNTIFS('Detalle por mesa'!$B:$B,$B8,'Detalle por mesa'!$G:$G,"Principal") -> 5 | K8: =COUNTIFS('Detalle por mesa'!$B:$B,$B8,'Detalle por mesa'!$G:$G,"Secundario") -> 7 | L8: Alcaldías Locales 1, 2 y 3; Instituto Distrital de Acción Comunal (IDACC); Secretaría de Participación y Desarrollo Social (SPD/UMATA); Asociaciones de Juntas de Acción Comunal (ASOJAC) (+1 más; ver hoja Detalle) | M8: 25 | N8: =M8/$M$42 -> 0.01 | O8: ='Proyección ±500'!F30 -> 25
B9: Punta Canoa | C9: Por definir | D9: Por definir | E9: Por definir | F9: Comunitaria | G9: Ambiental | H9: =COUNTIFS('Detalle por mesa'!$B:$B,$B9,'Detalle por mesa'!$I:$I,"Principal")+COUNTIFS('Detalle por mesa'!$B:$B,$B9,'Detalle por mesa'!$I:$I,"Secundario") -> 4 | I9: =COUNTIF('Detalle por mesa'!$B:$B,$B9) -> 12 | J9: =COUNTIFS('Detalle por mesa'!$B:$B,$B9,'Detalle por mesa'!$G:$G,"Principal") -> 5 | K9: =COUNTIFS('Detalle por mesa'!$B:$B,$B9,'Detalle por mesa'!$G:$G,"Secundario") -> 7 | L9: Alcaldías Locales 1, 2 y 3; Instituto Distrital de Acción Comunal (IDACC); Secretaría de Participación y Desarrollo Social (SPD/UMATA); Asociaciones de Juntas de Acción Comunal (ASOJAC) (+1 más; ver hoja Detalle) | M9: 20 | N9: =M9/$M$42 -> 0.008 | O9: ='Proyección ±500'!F31 -> 25
B10: Bayunca | C10: Por definir | D10: Por definir | E10: Por definir | F10: Comunitaria | G10: Ambiental | H10: =COUNTIFS('Detalle por mesa'!$B:$B,$B10,'Detalle por mesa'!$I:$I,"Principal")+COUNTIFS('Detalle por mesa'!$B:$B,$B10,'Detalle por mesa'!$I:$I,"Secundario") -> 3 | I10: =COUNTIF('Detalle por mesa'!$B:$B,$B10) -> 11 | J10: =COUNTIFS('Detalle por mesa'!$B:$B,$B10,'Detalle por mesa'!$G:$G,"Principal") -> 5 | K10: =COUNTIFS('Detalle por mesa'!$B:$B,$B10,'Detalle por mesa'!$G:$G,"Secundario") -> 6 | L10: Alcaldías Locales 1, 2 y 3; Instituto Distrital de Acción Comunal (IDACC); Secretaría de Participación y Desarrollo Social (SPD/UMATA); Asociaciones de Juntas de Acción Comunal (ASOJAC) (+1 más; ver hoja Detalle) | M10: 65 | N10: =M10/$M$42 -> 0.026 | O10: ='Proyección ±500'!F32 -> 90
B11: Pasacaballos | C11: Por definir | D11: Por definir | E11: Por definir | F11: Comunitaria | G11: Ambiental | H11: =COUNTIFS('Detalle por mesa'!$B:$B,$B11,'Detalle por mesa'!$I:$I,"Principal")+COUNTIFS('Detalle por mesa'!$B:$B,$B11,'Detalle por mesa'!$I:$I,"Secundario") -> 3 | I11: =COUNTIF('Detalle por mesa'!$B:$B,$B11) -> 12 | J11: =COUNTIFS('Detalle por mesa'!$B:$B,$B11,'Detalle por mesa'!$G:$G,"Principal") -> 6 | K11: =COUNTIFS('Detalle por mesa'!$B:$B,$B11,'Detalle por mesa'!$G:$G,"Secundario") -> 6 | L11: Alcaldías Locales 1, 2 y 3; Instituto Distrital de Acción Comunal (IDACC); Secretaría de Participación y Desarrollo Social (SPD/UMATA); Asociaciones de Juntas de Acción Comunal (ASOJAC) (+2 más; ver hoja Detalle) | M11: 50 | N11: =M11/$M$42 -> 0.02 | O11: ='Proyección ±500'!F33 -> 60
B12: Arroyo Grande | C12: Por definir | D12: Por definir | E12: Por definir | F12: Comunitaria | G12: Ambiental | H12: =COUNTIFS('Detalle por mesa'!$B:$B,$B12,'Detalle por mesa'!$I:$I,"Principal")+COUNTIFS('Detalle por mesa'!$B:$B,$B12,'Detalle por mesa'!$I:$I,"Secundario") -> 3 | I12: =COUNTIF('Detalle por mesa'!$B:$B,$B12) -> 11 | J12: =COUNTIFS('Detalle por mesa'!$B:$B,$B12,'Detalle por mesa'!$G:$G,"Principal") -> 5 | K12: =COUNTIFS('Detalle por mesa'!$B:$B,$B12,'Detalle por mesa'!$G:$G,"Secundario") -> 6 | L12: Alcaldías Locales 1, 2 y 3; Instituto Distrital de Acción Comunal (IDACC); Secretaría de Participación y Desarrollo Social (SPD/UMATA); Asociaciones de Juntas de Acción Comunal (ASOJAC) (+1 más; ver hoja Detalle) | M12: 25 | N12: =M12/$M$42 -> 0.01 | O12: ='Proyección ±500'!F34 -> 30
B13: Santa Ana | C13: Por definir | D13: Por definir | E13: Por definir | F13: Comunitaria | G13: Ambiental | H13: =COUNTIFS('Detalle por mesa'!$B:$B,$B13,'Detalle por mesa'!$I:$I,"Principal")+COUNTIFS('Detalle por mesa'!$B:$B,$B13,'Detalle por mesa'!$I:$I,"Secundario") -> 6 | I13: =COUNTIF('Detalle por mesa'!$B:$B,$B13) -> 16 | J13: =COUNTIFS('Detalle por mesa'!$B:$B,$B13,'Detalle por mesa'!$G:$G,"Principal") -> 6 | K13: =COUNTIFS('Detalle por mesa'!$B:$B,$B13,'Detalle por mesa'!$G:$G,"Secundario") -> 10 | L13: Alcaldías Locales 1, 2 y 3; Instituto Distrital de Acción Comunal (IDACC); Secretaría de Participación y Desarrollo Social (SPD/UMATA); Asociaciones de Juntas de Acción Comunal (ASOJAC) (+2 más; ver hoja Detalle) | M13: 30 | N13: =M13/$M$42 -> 0.012 | O13: ='Proyección ±500'!F35 -> 30
B14: Tierra bomba | C14: Por definir | D14: Por definir | E14: Por definir | F14: Comunitaria | G14: Ambiental | H14: =COUNTIFS('Detalle por mesa'!$B:$B,$B14,'Detalle por mesa'!$I:$I,"Principal")+COUNTIFS('Detalle por mesa'!$B:$B,$B14,'Detalle por mesa'!$I:$I,"Secundario") -> 6 | I14: =COUNTIF('Detalle por mesa'!$B:$B,$B14) -> 15 | J14: =COUNTIFS('Detalle por mesa'!$B:$B,$B14,'Detalle por mesa'!$G:$G,"Principal") -> 5 | K14: =COUNTIFS('Detalle por mesa'!$B:$B,$B14,'Detalle por mesa'!$G:$G,"Secundario") -> 10 | L14: Alcaldías Locales 1, 2 y 3; Instituto Distrital de Acción Comunal (IDACC); Secretaría de Participación y Desarrollo Social (SPD/UMATA); Asociaciones de Juntas de Acción Comunal (ASOJAC) (+1 más; ver hoja Detalle) | M14: 30 | N14: =M14/$M$42 -> 0.012 | O14: ='Proyección ±500'!F36 -> 35
B15: Bocachica | C15: Por definir | D15: Por definir | E15: Por definir | F15: Comunitaria | G15: Ambiental | H15: =COUNTIFS('Detalle por mesa'!$B:$B,$B15,'Detalle por mesa'!$I:$I,"Principal")+COUNTIFS('Detalle por mesa'!$B:$B,$B15,'Detalle por mesa'!$I:$I,"Secundario") -> 6 | I15: =COUNTIF('Detalle por mesa'!$B:$B,$B15) -> 15 | J15: =COUNTIFS('Detalle por mesa'!$B:$B,$B15,'Detalle por mesa'!$G:$G,"Principal") -> 5 | K15: =COUNTIFS('Detalle por mesa'!$B:$B,$B15,'Detalle por mesa'!$G:$G,"Secundario") -> 10 | L15: Alcaldías Locales 1, 2 y 3; Instituto Distrital de Acción Comunal (IDACC); Secretaría de Participación y Desarrollo Social (SPD/UMATA); Asociaciones de Juntas de Acción Comunal (ASOJAC) (+1 más; ver hoja Detalle) | M15: 30 | N15: =M15/$M$42 -> 0.012 | O15: ='Proyección ±500'!F37 -> 35
B16: Isla del Rosario | C16: Por definir | D16: Por definir | E16: Por definir | F16: Comunitaria | G16: Ambiental | H16: =COUNTIFS('Detalle por mesa'!$B:$B,$B16,'Detalle por mesa'!$I:$I,"Principal")+COUNTIFS('Detalle por mesa'!$B:$B,$B16,'Detalle por mesa'!$I:$I,"Secundario") -> 6 | I16: =COUNTIF('Detalle por mesa'!$B:$B,$B16) -> 15 | J16: =COUNTIFS('Detalle por mesa'!$B:$B,$B16,'Detalle por mesa'!$G:$G,"Principal") -> 5 | K16: =COUNTIFS('Detalle por mesa'!$B:$B,$B16,'Detalle por mesa'!$G:$G,"Secundario") -> 10 | L16: Alcaldías Locales 1, 2 y 3; Instituto Distrital de Acción Comunal (IDACC); Secretaría de Participación y Desarrollo Social (SPD/UMATA); Asociaciones de Juntas de Acción Comunal (ASOJAC) (+1 más; ver hoja Detalle) | M16: 20 | N16: =M16/$M$42 -> 0.008 | O16: ='Proyección ±500'!F38 -> 25
B17: Isla Fuerte | C17: Por definir | D17: Por definir | E17: Por definir | F17: Comunitaria | G17: Ambiental | H17: =COUNTIFS('Detalle por mesa'!$B:$B,$B17,'Detalle por mesa'!$I:$I,"Principal")+COUNTIFS('Detalle por mesa'!$B:$B,$B17,'Detalle por mesa'!$I:$I,"Secundario") -> 6 | I17: =COUNTIF('Detalle por mesa'!$B:$B,$B17) -> 15 | J17: =COUNTIFS('Detalle por mesa'!$B:$B,$B17,'Detalle por mesa'!$G:$G,"Principal") -> 5 | K17: =COUNTIFS('Detalle por mesa'!$B:$B,$B17,'Detalle por mesa'!$G:$G,"Secundario") -> 10 | L17: Alcaldías Locales 1, 2 y 3; Instituto Distrital de Acción Comunal (IDACC); Secretaría de Participación y Desarrollo Social (SPD/UMATA); Asociaciones de Juntas de Acción Comunal (ASOJAC) (+1 más; ver hoja Detalle) | M17: 25 | N17: =M17/$M$42 -> 0.01 | O17: ='Proyección ±500'!F39 -> 25
A19: Mesas Poblacionales | B19: Adulto mayor | C19: Por definir | D19: Por definir | E19: Por definir | F19: Comunitaria | G19: Personal | H19: =COUNTIFS('Detalle por mesa'!$B:$B,$B19,'Detalle por mesa'!$I:$I,"Principal")+COUNTIFS('Detalle por mesa'!$B:$B,$B19,'Detalle por mesa'!$I:$I,"Secundario") -> 1 | I19: =COUNTIF('Detalle por mesa'!$B:$B,$B19) -> 7 | J19: =COUNTIFS('Detalle por mesa'!$B:$B,$B19,'Detalle por mesa'!$G:$G,"Principal") -> 3 | K19: =COUNTIFS('Detalle por mesa'!$B:$B,$B19,'Detalle por mesa'!$G:$G,"Secundario") -> 4 | L19: Instituto Distrital de Deporte y Recreación (IDER); Secretaría de Participación y Desarrollo Social (SPD/UMATA); Asociación de Adultos Mayores de Cartagena | M19: 65 | N19: =M19/$M$42 -> 0.026 | O19: ='Proyección ±500'!F42 -> 80
B20: Infancia | C20: Por definir | D20: Por definir | E20: Por definir | F20: Personal | G20: Alimentaria; Comunitaria | H20: =COUNTIFS('Detalle por mesa'!$B:$B,$B20,'Detalle por mesa'!$I:$I,"Principal")+COUNTIFS('Detalle por mesa'!$B:$B,$B20,'Detalle por mesa'!$I:$I,"Secundario") -> 1 | I20: =COUNTIF('Detalle por mesa'!$B:$B,$B20) -> 8 | J20: =COUNTIFS('Detalle por mesa'!$B:$B,$B20,'Detalle por mesa'!$G:$G,"Principal") -> 4 | K20: =COUNTIFS('Detalle por mesa'!$B:$B,$B20,'Detalle por mesa'!$G:$G,"Secundario") -> 4 | L20: Secretaría de Educación Distrital (SED); Comisarías de Familia; Fundación Renacer; ICBF - Centro Zonal Cartagena | M20: 75 | N20: =M20/$M$42 -> 0.03 | O20: ='Proyección ±500'!F43 -> 90
B21: LGTBI | C21: Por definir | D21: Por definir | E21: Por definir | F21: Comunitaria | G21: Personal; Política | H21: =COUNTIFS('Detalle por mesa'!$B:$B,$B21,'Detalle por mesa'!$I:$I,"Principal")+COUNTIFS('Detalle por mesa'!$B:$B,$B21,'Detalle por mesa'!$I:$I,"Secundario") -> 3 | I21: =COUNTIF('Detalle por mesa'!$B:$B,$B21) -> 7 | J21: =COUNTIFS('Detalle por mesa'!$B:$B,$B21,'Detalle por mesa'!$G:$G,"Principal") -> 2 | K21: =COUNTIFS('Detalle por mesa'!$B:$B,$B21,'Detalle por mesa'!$G:$G,"Secundario") -> 5 | L21: Secretaría de Participación y Desarrollo Social (SPD/UMATA); Organización derecho a resistir | M21: 40 | N21: =M21/$M$42 -> 0.016 | O21: ='Proyección ±500'!F44 -> 45
B22: Discapacidad | C22: Por definir | D22: Por definir | E22: Por definir | F22: Comunitaria | G22: Política | H22: =COUNTIFS('Detalle por mesa'!$B:$B,$B22,'Detalle por mesa'!$I:$I,"Principal")+COUNTIFS('Detalle por mesa'!$B:$B,$B22,'Detalle por mesa'!$I:$I,"Secundario") -> 1 | I22: =COUNTIF('Detalle por mesa'!$B:$B,$B22) -> 6 | J22: =COUNTIFS('Detalle por mesa'!$B:$B,$B22,'Detalle por mesa'!$G:$G,"Principal") -> 3 | K22: =COUNTIFS('Detalle por mesa'!$B:$B,$B22,'Detalle por mesa'!$G:$G,"Secundario") -> 3 | L22: Instituto Distrital de Deporte y Recreación (IDER); Secretaría de Participación y Desarrollo Social (SPD/UMATA); Asociación de Personas con Discapacidad de Cartagena | M22: 45 | N22: =M22/$M$42 -> 0.018 | O22: ='Proyección ±500'!F45 -> 50
B23: Juventud | C23: Por definir | D23: Por definir | E23: Por definir | F23: Comunitaria | G23: Personal; Económica | H23: =COUNTIFS('Detalle por mesa'!$B:$B,$B23,'Detalle por mesa'!$I:$I,"Principal")+COUNTIFS('Detalle por mesa'!$B:$B,$B23,'Detalle por mesa'!$I:$I,"Secundario") -> 1 | I23: =COUNTIF('Detalle por mesa'!$B:$B,$B23) -> 10 | J23: =COUNTIFS('Detalle por mesa'!$B:$B,$B23,'Detalle por mesa'!$G:$G,"Principal") -> 5 | K23: =COUNTIFS('Detalle por mesa'!$B:$B,$B23,'Detalle por mesa'!$G:$G,"Secundario") -> 5 | L23: Escuela de Gobierno y Liderazgo; Instituto Distrital de Deporte y Recreación (IDER); Corporación Jóvenes por la Paz; Plataforma de Juventudes de Cartagena (+1 más; ver hoja Detalle) | M23: 80 | N23: =M23/$M$42 -> 0.032 | O23: ='Proyección ±500'!F46 -> 95
B24: Mujeres | C24: Por definir | D24: Por definir | E24: Por definir | F24: Personal | G24: Comunitaria | H24: =COUNTIFS('Detalle por mesa'!$B:$B,$B24,'Detalle por mesa'!$I:$I,"Principal")+COUNTIFS('Detalle por mesa'!$B:$B,$B24,'Detalle por mesa'!$I:$I,"Secundario") -> 3 | I24: =COUNTIF('Detalle por mesa'!$B:$B,$B24) -> 11 | J24: =COUNTIFS('Detalle por mesa'!$B:$B,$B24,'Detalle por mesa'!$G:$G,"Principal") -> 6 | K24: =COUNTIFS('Detalle por mesa'!$B:$B,$B24,'Detalle por mesa'!$G:$G,"Secundario") -> 5 | L24: Secretaría de Participación y Desarrollo Social (SPD/UMATA); Casa de la Mujer (violeta); Comisarías de Familia; Corporación Mujeres Tejiendo Paz (+2 más; ver hoja Detalle) | M24: 100 | N24: =M24/$M$42 -> 0.04 | O24: ='Proyección ±500'!F47 -> 125
B25: Victimas | C25: Por definir | D25: Por definir | E25: Por definir | F25: Política | G25: Comunitaria; Personal | H25: =COUNTIFS('Detalle por mesa'!$B:$B,$B25,'Detalle por mesa'!$I:$I,"Principal")+COUNTIFS('Detalle por mesa'!$B:$B,$B25,'Detalle por mesa'!$I:$I,"Secundario") -> 4 | I25: =COUNTIF('Detalle por mesa'!$B:$B,$B25) -> 10 | J25: =COUNTIFS('Detalle por mesa'!$B:$B,$B25,'Detalle por mesa'!$G:$G,"Principal") -> 5 | K25: =COUNTIFS('Detalle por mesa'!$B:$B,$B25,'Detalle por mesa'!$G:$G,"Secundario") -> 5 | L25: Defensoría del Pueblo (Regional Bolívar); Fundación Juan Luis Londoño; Mesa de Víctimas de Cartagena; Personería Distrital (+1 más; ver hoja Detalle) | M25: 60 | N25: =M25/$M$42 -> 0.024 | O25: ='Proyección ±500'!F48 -> 70
B26: Étnica | C26: Por definir | D26: Por definir | E26: Por definir | F26: Comunitaria | G26: — | H26: =COUNTIFS('Detalle por mesa'!$B:$B,$B26,'Detalle por mesa'!$I:$I,"Principal")+COUNTIFS('Detalle por mesa'!$B:$B,$B26,'Detalle por mesa'!$I:$I,"Secundario") -> 2 | I26: =COUNTIF('Detalle por mesa'!$B:$B,$B26) -> 8 | J26: =COUNTIFS('Detalle por mesa'!$B:$B,$B26,'Detalle por mesa'!$G:$G,"Principal") -> 3 | K26: =COUNTIFS('Detalle por mesa'!$B:$B,$B26,'Detalle por mesa'!$G:$G,"Secundario") -> 5 | L26: Consejo Comunitario de la Comunidad Negra de Pasacaballos; Consejo Comunitario de la Comunidad Negra de la Isla de Barú; Red de Jóvenes Afrodescendientes de Cartagena | M26: 80 | N26: =M26/$M$42 -> 0.032 | O26: ='Proyección ±500'!F49 -> 100
B27: Migrantes y refugiados (nueva) | C27: Por definir | D27: Por definir | E27: Por definir | F27: Personal | G27: Política; Comunitaria | H27: =COUNTIFS('Detalle por mesa'!$B:$B,$B27,'Detalle por mesa'!$I:$I,"Principal")+COUNTIFS('Detalle por mesa'!$B:$B,$B27,'Detalle por mesa'!$I:$I,"Secundario") -> 3 | I27: =COUNTIF('Detalle por mesa'!$B:$B,$B27) -> 10 | J27: =COUNTIFS('Detalle por mesa'!$B:$B,$B27,'Detalle por mesa'!$G:$G,"Principal") -> 5 | K27: =COUNTIFS('Detalle por mesa'!$B:$B,$B27,'Detalle por mesa'!$G:$G,"Secundario") -> 5 | L27: ACNUR - Agencia de la ONU para los Refugiados; Asociación de Venezolanos en Cartagena (AVEC); Fundación Colombia Somos Todos; Migración Colombia (Regional Bolívar) (+1 más; ver hoja Detalle) | M27: 55 | N27: =M27/$M$42 -> 0.022 | O27: ='Proyección ±500'!F50 -> 65
A29: Mesas Sectoriales | B29: Cultura | C29: Por definir | D29: Por definir | E29: Por definir | F29: Comunitaria | G29: Económica | H29: =COUNTIFS('Detalle por mesa'!$B:$B,$B29,'Detalle por mesa'!$I:$I,"Principal")+COUNTIFS('Detalle por mesa'!$B:$B,$B29,'Detalle por mesa'!$I:$I,"Secundario") -> 0 | I29: =COUNTIF('Detalle por mesa'!$B:$B,$B29) -> 6 | J29: =COUNTIFS('Detalle por mesa'!$B:$B,$B29,'Detalle por mesa'!$G:$G,"Principal") -> 3 | K29: =COUNTIFS('Detalle por mesa'!$B:$B,$B29,'Detalle por mesa'!$G:$G,"Secundario") -> 3 | L29: Escuela Taller de Cartagena de Indias (ETCAR); Instituto de Patrimonio y Cultura de Cartagena (IPCC); Universidad de Bellas Artes | M29: 30 | N29: =M29/$M$42 -> 0.012 | O29: ='Proyección ±500'!F53 -> 35
B30: Deporte | C30: Por definir | D30: Por definir | E30: Por definir | F30: Comunitaria | G30: Salud y sanitaria | H30: =COUNTIFS('Detalle por mesa'!$B:$B,$B30,'Detalle por mesa'!$I:$I,"Principal")+COUNTIFS('Detalle por mesa'!$B:$B,$B30,'Detalle por mesa'!$I:$I,"Secundario") -> 0 | I30: =COUNTIF('Detalle por mesa'!$B:$B,$B30) -> 6 | J30: =COUNTIFS('Detalle por mesa'!$B:$B,$B30,'Detalle por mesa'!$G:$G,"Principal") -> 1 | K30: =COUNTIFS('Detalle por mesa'!$B:$B,$B30,'Detalle por mesa'!$G:$G,"Secundario") -> 5 | L30: Instituto Distrital de Deporte y Recreación (IDER) | M30: 30 | N30: =M30/$M$42 -> 0.012 | O30: ='Proyección ±500'!F54 -> 35
B31: Salud | C31: Por definir | D31: Por definir | E31: Por definir | F31: Salud y sanitaria | G31: — | H31: =COUNTIFS('Detalle por mesa'!$B:$B,$B31,'Detalle por mesa'!$I:$I,"Principal")+COUNTIFS('Detalle por mesa'!$B:$B,$B31,'Detalle por mesa'!$I:$I,"Secundario") -> 1 | I31: =COUNTIF('Detalle por mesa'!$B:$B,$B31) -> 6 | J31: =COUNTIFS('Detalle por mesa'!$B:$B,$B31,'Detalle por mesa'!$G:$G,"Principal") -> 2 | K31: =COUNTIFS('Detalle por mesa'!$B:$B,$B31,'Detalle por mesa'!$G:$G,"Secundario") -> 4 | L31: Departamento Administrativo Distrital de Salud (DADIS); Universidad del Sinú | M31: 30 | N31: =M31/$M$42 -> 0.012 | O31: ='Proyección ±500'!F55 -> 35
B32: Educacion | C32: Por definir | D32: Por definir | E32: Por definir | F32: Comunitaria | G32: Económica | H32: =COUNTIFS('Detalle por mesa'!$B:$B,$B32,'Detalle por mesa'!$I:$I,"Principal")+COUNTIFS('Detalle por mesa'!$B:$B,$B32,'Detalle por mesa'!$I:$I,"Secundario") -> 0 | I32: =COUNTIF('Detalle por mesa'!$B:$B,$B32) -> 15 | J32: =COUNTIFS('Detalle por mesa'!$B:$B,$B32,'Detalle por mesa'!$G:$G,"Principal") -> 6 | K32: =COUNTIFS('Detalle por mesa'!$B:$B,$B32,'Detalle por mesa'!$G:$G,"Secundario") -> 9 | L32: Escuela Taller de Cartagena de Indias (ETCAR); Institución Universitaria Mayor de Cartagena (Colmayor); Secretaría de Educación Distrital (SED); SENA - Regional Bolívar (+2 más; ver hoja Detalle) | M32: 35 | N32: =M32/$M$42 -> 0.014 | O32: ='Proyección ±500'!F56 -> 40
B33: Movilidad y Espacio Público | C33: Por definir | D33: Por definir | E33: Por definir | F33: Económica | G33: Personal | H33: =COUNTIFS('Detalle por mesa'!$B:$B,$B33,'Detalle por mesa'!$I:$I,"Principal")+COUNTIFS('Detalle por mesa'!$B:$B,$B33,'Detalle por mesa'!$I:$I,"Secundario") -> 2 | I33: =COUNTIF('Detalle por mesa'!$B:$B,$B33) -> 8 | J33: =COUNTIFS('Detalle por mesa'!$B:$B,$B33,'Detalle por mesa'!$G:$G,"Principal") -> 5 | K33: =COUNTIFS('Detalle por mesa'!$B:$B,$B33,'Detalle por mesa'!$G:$G,"Secundario") -> 3 | L33: Departamento Administrativo de Tránsito y Transporte (DATT); Gerencia de Espacio Público y Movilidad (GEPM); Transcaribe S.A.; Asociación de Trabajadores Informales de Cartagena (+1 más; ver hoja Detalle) | M33: 30 | N33: =M33/$M$42 -> 0.012 | O33: ='Proyección ±500'!F57 -> 35
B34: Servicios públicos, infraestructura y vivienda | C34: Por definir | D34: Por definir | E34: Por definir | F34: Ambiental | G34: Económica; Comunitaria | H34: =COUNTIFS('Detalle por mesa'!$B:$B,$B34,'Detalle por mesa'!$I:$I,"Principal")+COUNTIFS('Detalle por mesa'!$B:$B,$B34,'Detalle por mesa'!$I:$I,"Secundario") -> 1 | I34: =COUNTIF('Detalle por mesa'!$B:$B,$B34) -> 11 | J34: =COUNTIFS('Detalle por mesa'!$B:$B,$B34,'Detalle por mesa'!$G:$G,"Principal") -> 5 | K34: =COUNTIFS('Detalle por mesa'!$B:$B,$B34,'Detalle por mesa'!$G:$G,"Secundario") -> 6 | L34: Corvivienda; Secretaría General (Oficina de Servicios Públicos - Oficina Asesora Informática); Secretaría de Infraestructura; Líderes de Islas (Tierra Bomba, Barú, etc) (+1 más; ver hoja Detalle) | M34: 35 | N34: =M34/$M$42 -> 0.014 | O34: ='Proyección ±500'!F58 -> 40
B35: Seguridad y Convivencia Ciudadana | C35: Por definir | D35: Por definir | E35: Por definir | F35: Personal | G35: — | H35: =COUNTIFS('Detalle por mesa'!$B:$B,$B35,'Detalle por mesa'!$I:$I,"Principal")+COUNTIFS('Detalle por mesa'!$B:$B,$B35,'Detalle por mesa'!$I:$I,"Secundario") -> 6 | I35: =COUNTIF('Detalle por mesa'!$B:$B,$B35) -> 38 | J35: =COUNTIFS('Detalle por mesa'!$B:$B,$B35,'Detalle por mesa'!$G:$G,"Principal") -> 24 | K35: =COUNTIFS('Detalle por mesa'!$B:$B,$B35,'Detalle por mesa'!$G:$G,"Secundario") -> 14 | L35: Departamento Administrativo de Tránsito y Transporte (DATT); Distriseguridad; Secretaría de Interior y Convivencia Ciudadana (SICC); Asociación de Comerciantes del Centro Histórico (+20 más; ver hoja Detalle) | M35: 40 | N35: =M35/$M$42 -> 0.016 | O35: ='Proyección ±500'!F59 -> 50
B36: Medio ambiente, Gestión del riesgo y Planeación | C36: Por definir | D36: Por definir | E36: Por definir | F36: Ambiental | G36: Política | H36: =COUNTIFS('Detalle por mesa'!$B:$B,$B36,'Detalle por mesa'!$I:$I,"Principal")+COUNTIFS('Detalle por mesa'!$B:$B,$B36,'Detalle por mesa'!$I:$I,"Secundario") -> 12 | I36: =COUNTIF('Detalle por mesa'!$B:$B,$B36) -> 24 | J36: =COUNTIFS('Detalle por mesa'!$B:$B,$B36,'Detalle por mesa'!$G:$G,"Principal") -> 15 | K36: =COUNTIFS('Detalle por mesa'!$B:$B,$B36,'Detalle por mesa'!$G:$G,"Secundario") -> 9 | L36: CARDIQUE; Corvivienda; Cuerpo Oficial de Bomberos; EPA Cartagena; Oficina Asesora para la Gestión del Riesgo y Desastres - OAGRD (+11 más; ver hoja Detalle) | M36: 40 | N36: =M36/$M$42 -> 0.016 | O36: ='Proyección ±500'!F60 -> 50
B37: Desarrollo económico, Turismo / Competitividad , ciencia y tecnología | C37: Por definir | D37: Por definir | E37: Por definir | F37: Económica | G37: — | H37: =COUNTIFS('Detalle por mesa'!$B:$B,$B37,'Detalle por mesa'!$I:$I,"Principal")+COUNTIFS('Detalle por mesa'!$B:$B,$B37,'Detalle por mesa'!$I:$I,"Secundario") -> 0 | I37: =COUNTIF('Detalle por mesa'!$B:$B,$B37) -> 28 | J37: =COUNTIFS('Detalle por mesa'!$B:$B,$B37,'Detalle por mesa'!$G:$G,"Principal") -> 21 | K37: =COUNTIFS('Detalle por mesa'!$B:$B,$B37,'Detalle por mesa'!$G:$G,"Secundario") -> 7 | L37: Corvivienda; Escuela Taller de Cartagena de Indias (ETCAR); Gerencia de Espacio Público y Movilidad (GEPM); Institución Universitaria Mayor de Cartagena (Colmayor) (+17 más; ver hoja Detalle) | M37: 40 | N37: =M37/$M$42 -> 0.016 | O37: ='Proyección ±500'!F61 -> 50
B38: Transparencia y Cultura Ciudadana | C38: Por definir | D38: Por definir | E38: Por definir | F38: Política | G38: — | H38: =COUNTIFS('Detalle por mesa'!$B:$B,$B38,'Detalle por mesa'!$I:$I,"Principal")+COUNTIFS('Detalle por mesa'!$B:$B,$B38,'Detalle por mesa'!$I:$I,"Secundario") -> 2 | I38: =COUNTIF('Detalle por mesa'!$B:$B,$B38) -> 35 | J38: =COUNTIFS('Detalle por mesa'!$B:$B,$B38,'Detalle por mesa'!$G:$G,"Principal") -> 23 | K38: =COUNTIFS('Detalle por mesa'!$B:$B,$B38,'Detalle por mesa'!$G:$G,"Secundario") -> 12 | L38: Secretaría General (Oficina de Servicios Públicos - Oficina Asesora Informática); Secretaría de Planeación Distrital; ACNUR - Agencia de la ONU para los Refugiados; Caracol Radio - Cartagena (+19 más; ver hoja Detalle) | M38: 45 | N38: =M38/$M$42 -> 0.018 | O38: ='Proyección ±500'!F62 -> 55
B39: Mesa de Construcción de Paz | C39: Por definir | D39: Por definir | E39: Por definir | F39: Política | G39: Personal; Comunitaria | H39: =COUNTIFS('Detalle por mesa'!$B:$B,$B39,'Detalle por mesa'!$I:$I,"Principal")+COUNTIFS('Detalle por mesa'!$B:$B,$B39,'Detalle por mesa'!$I:$I,"Secundario") -> 2 | I39: =COUNTIF('Detalle por mesa'!$B:$B,$B39) -> 17 | J39: =COUNTIFS('Detalle por mesa'!$B:$B,$B39,'Detalle por mesa'!$G:$G,"Principal") -> 11 | K39: =COUNTIFS('Detalle por mesa'!$B:$B,$B39,'Detalle por mesa'!$G:$G,"Secundario") -> 6 | L39: ACNUR - Agencia de la ONU para los Refugiados; Corporación Jóvenes por la Paz; Corporación Mujeres Tejiendo Paz; Defensoría del Pueblo (Regional Bolívar) (+7 más; ver hoja Detalle) | M39: 35 | N39: =M39/$M$42 -> 0.014 | O39: ='Proyección ±500'!F63 -> 45
B40: Seguridad alimentaria (nueva) | C40: Por definir | D40: Por definir | E40: Por definir | F40: Alimentaria | G40: — | H40: =COUNTIFS('Detalle por mesa'!$B:$B,$B40,'Detalle por mesa'!$I:$I,"Principal")+COUNTIFS('Detalle por mesa'!$B:$B,$B40,'Detalle por mesa'!$I:$I,"Secundario") -> 0 | I40: =COUNTIF('Detalle por mesa'!$B:$B,$B40) -> 5 | J40: =COUNTIFS('Detalle por mesa'!$B:$B,$B40,'Detalle por mesa'!$G:$G,"Principal") -> 1 | K40: =COUNTIFS('Detalle por mesa'!$B:$B,$B40,'Detalle por mesa'!$G:$G,"Secundario") -> 4 | L40: Secretaría de Educación Distrital (SED) | M40: 30 | N40: =M40/$M$42 -> 0.012 | O40: ='Proyección ±500'!F64 -> 35
A42: Total de mesas | B42: =COUNTA(B3:B40) -> 35 | H42: =SUM(H3:H40) -> 105 | I42: =SUM(I3:I40) -> 476 | J42: =SUM(J3:J40) -> 233 | K42: =SUM(K3:K40) -> 243 | M42: =SUM(M3:M40) -> 2500 | O42: =SUM(O3:O40) -> 3000
A43: Mesas por clasificación
A44: Mesas Territoriales | B44: =COUNTA(B3:B5) -> 3
...

Sheet Metas de convocatoria
A1: METAS DE CONVOCATORIA POR MESA
A2: Texto en azul = dato que se puede editar; celdas amarillas = cifra estimada o provisional por verificar. Todo lo demás se recalcula solo.
A3: PARÁMETROS | C3: Valor | D3: Criterio
A4: Meta total de personas | C4: 2500 | D4: Meta definida para el conjunto de las 35 mesas.
A5: Meta Localidad Histórica y del Caribe Norte | C5: 350 | D5: Definida: 350 personas por reunión de localidad.
A6: Meta Localidad De La Virgen y Turística | C6: 400 | D6: Definida: 400 por su peso demográfico (36,2% de la población en el Censo 2018).
A7: Meta Localidad Industrial y de la Bahía | C7: 350 | D7: Definida: 350 personas por reunión de localidad.
A8: Subtotal localidades | C8: =SUM(C5:C7) -> 1100 | D8: Cifra fija; el resto se reparte entre las otras 32 mesas.
A9: Bloque: mesas rurales (11) | C9: 380 | D9: Propuesta: piso de 20 personas por corregimiento más el excedente según población. Equivale a 15% de la meta, por encima del 10,6% de población rural, para que los corregimientos pequeños tengan una reunión viable.
A10: Bloque: mesas poblacionales (9) | C10: 600 | D10: Propuesta: 24% de la meta; son grupos grandes y con alta superposición entre sí (por ejemplo, mujeres y víctimas).
A11: Bloque: mesas sectoriales (12) | C11: =C4-C8-C9-C10 -> 420 | D11: Es el saldo: meta total menos localidades, rurales y poblacionales.
A12: Piso mínimo por mesa rural | C12: 20 | D12: Propuesta: reunión comunitaria mínima viable.
A13: Piso mínimo por mesa poblacional | C13: 30 | D13: Propuesta: evita que los grupos pequeños (LGTBI, discapacidad) queden con metas simbólicas.
A14: Piso mínimo por mesa sectorial | C14: 20 | D14: Propuesta.
A15: Exponente de ponderación: rurales | C15: 1 | D15: 1 = proporcional a la población; 0,5 = atenúa diferencias; 0 = todas iguales.
A16: Exponente de ponderación: poblacionales | C16: 0.5 | D16: 0,5 = raíz cuadrada de la población. Con 1, "mujeres" (524 mil) absorbería casi todo el bloque.
A17: Exponente de ponderación: sectoriales | C17: 0.5 | D17: Los sectoriales convocan organizaciones, no residentes; se ponderan por el número de actores de la matriz.
A18: Población de Cartagena 2025 (proyección DANE) | C18: 1011520 | D18: Planeación Distrital con datos DANE (El Universal, ago. 2025).
A19: Población censada 2018 (DANE) | C19: 887666 | D19: Síntesis del Diagnóstico Territorial del POT, Planeación Distrital 2025.
A20: Población de Cartagena 2024 (proyección DANE) | C20: 1010408 | D20: Síntesis del Diagnóstico Territorial del POT, Planeación Distrital 2025.
A22: MESAS TERRITORIALES
A23: Clasificación | B23: Mesa | C23: Población aprox. (Censo 2018 × peso) | D23: Peso de la localidad (Censo 2018) | F23: Meta si fuera estrictamente proporcional (referencia) | G23: Meta de personas | H23: Meta / población | I23: Fuente y nota
A24: Mesas Territoriales | B24: Localidad Histórica y del Caribe Norte | C24: =ROUND($C$19*D24,0) -> 242067 | D24: 0.2727 | F24: =ROUND($C$8*D24/SUM($D$24:$D$26),0) -> 303 | G24: =$C$5 -> 350 | H24: =G24/C24 -> 0.0014458807 | I24: Meta fijada por el equipo. Pesos de la localidad: Síntesis del Diagnóstico Territorial del POT (Planeación Distrital 2025), Censo 2018.
A25: Mesas Territoriales | B25: Localidad De La Virgen y Turística | C25: =ROUND($C$19*D25,0) -> 321246 | D25: 0.3619 | F25: =ROUND($C$8*D25/SUM($D$24:$D$26),0) -> 403 | G25: =$C$6 -> 400 | H25: =G25/C25 -> 0.0012451517 | I25: Meta fijada por el equipo. Pesos de la localidad: Síntesis del Diagnóstico Territorial del POT (Planeación Distrital 2025), Censo 2018.
A26: Mesas Territoriales | B26: Localidad Industrial y de la Bahía | C26: =ROUND($C$19*D26,0) -> 314411 | D26: 0.3542 | F26: =ROUND($C$8*D26/SUM($D$24:$D$26),0) -> 394 | G26: =$C$7 -> 350 | H26: =G26/C26 -> 0.0011131926 | I26: Meta fijada por el equipo. Pesos de la localidad: Síntesis del Diagnóstico Territorial del POT (Planeación Distrital 2025), Censo 2018.
A27: Subtotal Mesas Territoriales | G27: =SUM(G24:G26) -> 1100
A29: MESAS RURALES
A30: Clasificación | B30: Mesa | C30: Población del corregimiento | D30: Calidad del dato | E30: Peso | F30: Meta calculada | G30: Meta de personas | H30: Meta / población | I30: Fuente y nota
A31: Mesas Rurales | B31: Boquilla | C31: 14106 | D31: Oficial | E31: =POWER(C31,$C$15) -> 14106 | F31: =$C$12+($C$9-11*$C$12)*E31/SUM($E$31:$E$41) -> 58.176559 | G31: =ROUND(F31/5,0)*5 -> 60 | H31: =G31/C31 -> 0.0042535091 | I31: POT, Documento resumen (seguimientopot.cartagena.gov.co); la fuente no indica el año de la cifra.
A32: Mesas Rurales | B32: Arroyo de Piedra | C32: 1599 | D32: Oficial | E32: =POWER(C32,$C$15) -> 1599 | F32: =$C$12+($C$9-11*$C$12)*E32/SUM($E$31:$E$41) -> 24.327543 | G32: =ROUND(F32/5,0)*5 -> 25 | H32: =G32/C32 -> 0.015634772 | I32: POT, Documento resumen (seguimientopot.cartagena.gov.co); la fuente no indica el año de la cifra.
A33: Mesas Rurales | B33: Punta Canoa | C33: 815 | D33: Oficial | E33: =POWER(C33,$C$15) -> 815 | F33: =$C$12+($C$9-11*$C$12)*E33/SUM($E$31:$E$41) -> 22.205721 | G33: =ROUND(F33/5,0)*5 -> 20 | H33: =G33/C33 -> 0.024539877 | I33: POT, Documento resumen (seguimientopot.cartagena.gov.co); la fuente no indica el año de la cifra.
A34: Mesas Rurales | B34: Bayunca | C34: =ROUND(8107/0.518,-2) -> 15700 | D34: Estimación | E34: =POWER(C34,$C$15) -> 15700 | F34: =$C$12+($C$9-11*$C$12)*E34/SUM($E$31:$E$41) -> 62.49057 | G34: =$C$9-(SUM(G31:G33)+SUM(G35:G41)) -> 65 | H34: =G34/C34 -> 0.0041401274 | I34: Estimación: 8.107 mujeres en Bayunca (Censo 2018, Planeación Distrital) ÷ 51,8% de mujeres. Verificar. Esta fila absorbe el redondeo para que el bloque cuadre.
A35: Mesas Rurales | B35: Pasacaballos | C35: 10648 | D35: Oficial | E35: =POWER(C35,$C$15) -> 10648 | F35: =$C$12+($C$9-11*$C$12)*E35/SUM($E$31:$E$41) -> 48.817808 | G35: =ROUND(F35/5,0)*5 -> 50 | H35: =G35/C35 -> 0.0046957175 | I35: POT, Documento resumen (seguimientopot.cartagena.gov.co); la fuente no indica el año de la cifra.
A36: Mesas Rurales | B36: Arroyo Grande | C36: 2380 | D36: Oficial | E36: =POWER(C36,$C$15) -> 2380 | F36: =$C$12+($C$9-11*$C$12)*E36/SUM($E$31:$E$41) -> 26.441246 | G36: =ROUND(F36/5,0)*5 -> 25 | H36: =G36/C36 -> 0.010504202 | I36: POT, Documento resumen (seguimientopot.cartagena.gov.co); la fuente no indica el año de la cifra.
A37: Mesas Rurales | B37: Santa Ana | C37: 2990 | D37: Oficial | E37: =POWER(C37,$C$15) -> 2990 | F37: =$C$12+($C$9-11*$C$12)*E37/SUM($E$31:$E$41) -> 28.092153 | G37: =ROUND(F37/5,0)*5 -> 30 | H37: =G37/C37 -> 0.010033445 | I37: POT, Documento resumen (seguimientopot.cartagena.gov.co); la fuente no indica el año de la cifra.
A38: Mesas Rurales | B38: Tierra bomba | C38: 4300 | D38: Provisional | E38: =POWER(C38,$C$15) -> 4300 | F38: =$C$12+($C$9-11*$C$12)*E38/SUM($E$31:$E$41) -> 31.637545 | G38: =ROUND(F38/5,0)*5 -> 30 | H38: =G38/C38 -> 0.0069767442 | I38: Provisional: no hallé cifra oficial; se asumió similar a Bocachica (misma isla). Reemplazar con el dato de Planeación.
A39: Mesas Rurales | B39: Bocachica | C39: 4269 | D39: Oficial | E39: =POWER(C39,$C$15) -> 4269 | F39: =$C$12+($C$9-11*$C$12)*E39/SUM($E$31:$E$41) -> 31.553646 | G39: =ROUND(F39/5,0)*5 -> 30 | H39: =G39/C39 -> 0.0070274069 | I39: POT, Documento resumen (seguimientopot.cartagena.gov.co); la fuente no indica el año de la cifra.
A40: Mesas Rurales | B40: Isla del Rosario | C40: 735 | D40: Oficial | E40: =POWER(C40,$C$15) -> 735 | F40: =$C$12+($C$9-11*$C$12)*E40/SUM($E$31:$E$41) -> 21.989208 | G40: =ROUND(F40/5,0)*5 -> 20 | H40: =G40/C40 -> 0.027210884 | I40: POT, Documento resumen (seguimientopot.cartagena.gov.co); la fuente no indica el año de la cifra.
A41: Mesas Rurales | B41: Isla Fuerte | C41: 1577 | D41: Oficial | E41: =POWER(C41,$C$15) -> 1577 | F41: =$C$12+($C$9-11*$C$12)*E41/SUM($E$31:$E$41) -> 24.268002 | G41: =ROUND(F41/5,0)*5 -> 25 | H41: =G41/C41 -> 0.015852885 | I41: POT, Documento resumen (seguimientopot.cartagena.gov.co); la fuente no indica el año de la cifra.
A42: Subtotal Mesas Rurales | G42: =SUM(G31:G41) -> 380
...

Sheet Proyección ±500
A1: PROYECCIÓN DE CONVOCATORIA CON MARGEN DE ERROR (±500 PERSONAS)
A2: Tres escenarios para las 35 mesas: mínimo (meta − margen), central (meta) y máximo (meta + margen). Se aplica el mismo método de la hoja "Metas de convocatoria" (piso por mesa + reparto por peso). Texto azul = dato editable; verde = vínculo a otra hoja; el resto se recalcula solo.
A4: PARÁMETROS | C4: Valor | D4: Criterio
A5: Meta central de personas | C5: ='Metas de convocatoria'!C4 -> 2500 | D5: Vínculo a la meta total de la hoja "Metas de convocatoria" (2.500, definida por el equipo).
A6: Margen de error (personas) | C6: 500 | D6: Definido por el equipo: ±500 personas sobre la meta central.
A7: Escenario mínimo | C7: =C5-C6 -> 2000 | D7: Meta central menos el margen.
A8: Escenario máximo | C8: =C5+C6 -> 3000 | D8: Meta central más el margen.
A9: Margen relativo | C9: =C6/C5 -> 0.2 | D9: Proporción del margen sobre la meta central; se aplica por igual a localidades, rurales y poblacionales.
A10: Factor escenario mínimo | C10: =C7/C5 -> 0.8 | D10: Multiplica las metas de bloque del escenario central.
A11: Factor escenario máximo | C11: =C8/C5 -> 1.2 | D11: Multiplica las metas de bloque del escenario central.
A13: RESUMEN POR BLOQUE
A14: Bloque | B14: N° de mesas | C14: Mínimo | D14: Central | E14: Máximo | F14: Diferencia mín.–máx. | G14: % del total (central) | H14: Regla de cálculo
A15: Mesas Territoriales | B15: 3 | C15: =D27 -> 880 | D15: ='Metas de convocatoria'!C8 -> 1100 | E15: =F27 -> 1320 | F15: =E15-C15 -> 440 | G15: =D15/D$19 -> 0.44 | H15: Cada localidad: meta central × factor, redondeada a múltiplo de 5.
A16: Mesas Rurales | B16: 11 | C16: =ROUND(D16*$C$10/5,0)*5 -> 305 | D16: ='Metas de convocatoria'!C9 -> 380 | E16: =ROUND(D16*$C$11/5,0)*5 -> 455 | F16: =E16-C16 -> 150 | G16: =D16/D$19 -> 0.152 | H16: Bloque central × factor (múltiplo de 5); dentro del bloque, piso de 20 + reparto por población.
A17: Mesas Poblacionales | B17: 9 | C17: =ROUND(D17*$C$10/5,0)*5 -> 480 | D17: ='Metas de convocatoria'!C10 -> 600 | E17: =ROUND(D17*$C$11/5,0)*5 -> 720 | F17: =E17-C17 -> 240 | G17: =D17/D$19 -> 0.24 | H17: Bloque central × factor (múltiplo de 5); piso de 30 + reparto por raíz de la población.
A18: Mesas Sectoriales | B18: 12 | C18: =$C$7-SUM(C15:C17) -> 335 | D18: ='Metas de convocatoria'!C11 -> 420 | E18: =$C$8-SUM(E15:E17) -> 505 | F18: =E18-C18 -> 170 | G18: =D18/D$19 -> 0.168 | H18: Saldo: escenario total menos los otros tres bloques; piso de 20 + reparto por raíz del n° de actores.
A19: Total | B19: =SUM(B15:B18) -> 35 | C19: =SUM(C15:C18) -> 2000 | D19: =SUM(D15:D18) -> 2500 | E19: =SUM(E15:E18) -> 3000 | F19: =SUM(F15:F18) -> 1000 | G19: =SUM(G15:G18) -> 1 | H19: Debe coincidir con 2.000 / 2.500 / 3.000.
A22: PROYECCIÓN POR MESA
A23: Clasificación | B23: Mesa | C23: Peso (hoja Metas) | D23: Mínimo | E23: Central | F23: Máximo | G23: Diferencia mín.–máx. | H23: Nota
A24: Mesas Territoriales | B24: ='Metas de convocatoria'!B24 -> Localidad Histórica y del Caribe Norte | C24: — | D24: =ROUND('Metas de convocatoria'!C5*$C$10/5,0)*5 -> 280 | E24: ='Metas de convocatoria'!G24 -> 350 | F24: =ROUND('Metas de convocatoria'!C5*$C$11/5,0)*5 -> 420 | G24: =F24-D24 -> 140 | H24: Meta fija de la localidad × factor del escenario.
A25: Mesas Territoriales | B25: ='Metas de convocatoria'!B25 -> Localidad De La Virgen y Turística | C25: — | D25: =ROUND('Metas de convocatoria'!C6*$C$10/5,0)*5 -> 320 | E25: ='Metas de convocatoria'!G25 -> 400 | F25: =ROUND('Metas de convocatoria'!C6*$C$11/5,0)*5 -> 480 | G25: =F25-D25 -> 160 | H25: Meta fija de la localidad × factor del escenario.
A26: Mesas Territoriales | B26: ='Metas de convocatoria'!B26 -> Localidad Industrial y de la Bahía | C26: — | D26: =ROUND('Metas de convocatoria'!C7*$C$10/5,0)*5 -> 280 | E26: ='Metas de convocatoria'!G26 -> 350 | F26: =ROUND('Metas de convocatoria'!C7*$C$11/5,0)*5 -> 420 | G26: =F26-D26 -> 140 | H26: Meta fija de la localidad × factor del escenario.
A27: Subtotal Territoriales | D27: =SUM(D24:D26) -> 880 | E27: =SUM(E24:E26) -> 1100 | F27: =SUM(F24:F26) -> 1320 | G27: =SUM(G24:G26) -> 440
A29: Mesas Rurales | B29: ='Metas de convocatoria'!B31 -> Boquilla | C29: ='Metas de convocatoria'!E31 -> 14106 | D29: =ROUND(('Metas de convocatoria'!$C$12+(C$16-11*'Metas de convocatoria'!$C$12)*$C29/SUM($C$29:$C$39))/5,0)*5 -> 40 | E29: ='Metas de convocatoria'!G31 -> 60 | F29: =ROUND(('Metas de convocatoria'!$C$12+(E$16-11*'Metas de convocatoria'!$C$12)*$C29/SUM($C$29:$C$39))/5,0)*5 -> 75 | G29: =F29-D29 -> 35 | H29: Piso + reparto proporcional al peso.
A30: Mesas Rurales | B30: ='Metas de convocatoria'!B32 -> Arroyo de Piedra | C30: ='Metas de convocatoria'!E32 -> 1599 | D30: =ROUND(('Metas de convocatoria'!$C$12+(C$16-11*'Metas de convocatoria'!$C$12)*$C30/SUM($C$29:$C$39))/5,0)*5 -> 20 | E30: ='Metas de convocatoria'!G32 -> 25 | F30: =ROUND(('Metas de convocatoria'!$C$12+(E$16-11*'Metas de convocatoria'!$C$12)*$C30/SUM($C$29:$C$39))/5,0)*5 -> 25 | G30: =F30-D30 -> 5 | H30: Piso + reparto proporcional al peso.
A31: Mesas Rurales | B31: ='Metas de convocatoria'!B33 -> Punta Canoa | C31: ='Metas de convocatoria'!E33 -> 815 | D31: =ROUND(('Metas de convocatoria'!$C$12+(C$16-11*'Metas de convocatoria'!$C$12)*$C31/SUM($C$29:$C$39))/5,0)*5 -> 20 | E31: ='Metas de convocatoria'!G33 -> 20 | F31: =ROUND(('Metas de convocatoria'!$C$12+(E$16-11*'Metas de convocatoria'!$C$12)*$C31/SUM($C$29:$C$39))/5,0)*5 -> 25 | G31: =F31-D31 -> 5 | H31: Piso + reparto proporcional al peso.
A32: Mesas Rurales | B32: ='Metas de convocatoria'!B34 -> Bayunca | C32: ='Metas de convocatoria'!E34 -> 15700 | D32: =C$16-(SUM(D29:D31)+SUM(D33:D39)) -> 50 | E32: ='Metas de convocatoria'!G34 -> 65 | F32: =E$16-(SUM(F29:F31)+SUM(F33:F39)) -> 90 | G32: =F32-D32 -> 40 | H32: Fila de ajuste: absorbe el redondeo para que el bloque cuadre.
A33: Mesas Rurales | B33: ='Metas de convocatoria'!B35 -> Pasacaballos | C33: ='Metas de convocatoria'!E35 -> 10648 | D33: =ROUND(('Metas de convocatoria'!$C$12+(C$16-11*'Metas de convocatoria'!$C$12)*$C33/SUM($C$29:$C$39))/5,0)*5 -> 35 | E33: ='Metas de convocatoria'!G35 -> 50 | F33: =ROUND(('Metas de convocatoria'!$C$12+(E$16-11*'Metas de convocatoria'!$C$12)*$C33/SUM($C$29:$C$39))/5,0)*5 -> 60 | G33: =F33-D33 -> 25 | H33: Piso + reparto proporcional al peso.
A34: Mesas Rurales | B34: ='Metas de convocatoria'!B36 -> Arroyo Grande | C34: ='Metas de convocatoria'!E36 -> 2380 | D34: =ROUND(('Metas de convocatoria'!$C$12+(C$16-11*'Metas de convocatoria'!$C$12)*$C34/SUM($C$29:$C$39))/5,0)*5 -> 25 | E34: ='Metas de convocatoria'!G36 -> 25 | F34: =ROUND(('Metas de convocatoria'!$C$12+(E$16-11*'Metas de convocatoria'!$C$12)*$C34/SUM($C$29:$C$39))/5,0)*5 -> 30 | G34: =F34-D34 -> 5 | H34: Piso + reparto proporcional al peso.
A35: Mesas Rurales | B35: ='Metas de convocatoria'!B37 -> Santa Ana | C35: ='Metas de convocatoria'!E37 -> 2990 | D35: =ROUND(('Metas de convocatoria'!$C$12+(C$16-11*'Metas de convocatoria'!$C$12)*$C35/SUM($C$29:$C$39))/5,0)*5 -> 25 | E35: ='Metas de convocatoria'!G37 -> 30 | F35: =ROUND(('Metas de convocatoria'!$C$12+(E$16-11*'Metas de convocatoria'!$C$12)*$C35/SUM($C$29:$C$39))/5,0)*5 -> 30 | G35: =F35-D35 -> 5 | H35: Piso + reparto proporcional al peso.
A36: Mesas Rurales | B36: ='Metas de convocatoria'!B38 -> Tierra bomba | C36: ='Metas de convocatoria'!E38 -> 4300 | D36: =ROUND(('Metas de convocatoria'!$C$12+(C$16-11*'Metas de convocatoria'!$C$12)*$C36/SUM($C$29:$C$39))/5,0)*5 -> 25 | E36: ='Metas de convocatoria'!G38 -> 30 | F36: =ROUND(('Metas de convocatoria'!$C$12+(E$16-11*'Metas de convocatoria'!$C$12)*$C36/SUM($C$29:$C$39))/5,0)*5 -> 35 | G36: =F36-D36 -> 10 | H36: Piso + reparto proporcional al peso.
A37: Mesas Rurales | B37: ='Metas de convocatoria'!B39 -> Bocachica | C37: ='Metas de convocatoria'!E39 -> 4269 | D37: =ROUND(('Metas de convocatoria'!$C$12+(C$16-11*'Metas de convocatoria'!$C$12)*$C37/SUM($C$29:$C$39))/5,0)*5 -> 25 | E37: ='Metas de convocatoria'!G39 -> 30 | F37: =ROUND(('Metas de convocatoria'!$C$12+(E$16-11*'Metas de convocatoria'!$C$12)*$C37/SUM($C$29:$C$39))/5,0)*5 -> 35 | G37: =F37-D37 -> 10 | H37: Piso + reparto proporcional al peso.
A38: Mesas Rurales | B38: ='Metas de convocatoria'!B40 -> Isla del Rosario | C38: ='Metas de convocatoria'!E40 -> 735 | D38: =ROUND(('Metas de convocatoria'!$C$12+(C$16-11*'Metas de convocatoria'!$C$12)*$C38/SUM($C$29:$C$39))/5,0)*5 -> 20 | E38: ='Metas de convocatoria'!G40 -> 20 | F38: =ROUND(('Metas de convocatoria'!$C$12+(E$16-11*'Metas de convocatoria'!$C$12)*$C38/SUM($C$29:$C$39))/5,0)*5 -> 25 | G38: =F38-D38 -> 5 | H38: Piso + reparto proporcional al peso.
A39: Mesas Rurales | B39: ='Metas de convocatoria'!B41 -> Isla Fuerte | C39: ='Metas de convocatoria'!E41 -> 1577 | D39: =ROUND(('Metas de convocatoria'!$C$12+(C$16-11*'Metas de convocatoria'!$C$12)*$C39/SUM($C$29:$C$39))/5,0)*5 -> 20 | E39: ='Metas de convocatoria'!G41 -> 25 | F39: =ROUND(('Metas de convocatoria'!$C$12+(E$16-11*'Metas de convocatoria'!$C$12)*$C39/SUM($C$29:$C$39))/5,0)*5 -> 25 | G39: =F39-D39 -> 5 | H39: Piso + reparto proporcional al peso.
A40: Subtotal Rurales | D40: =SUM(D29:D39) -> 305 | E40: =SUM(E29:E39) -> 380 | F40: =SUM(F29:F39) -> 455 | G40: =SUM(G29:G39) -> 150
A42: Mesas Poblacionales | B42: ='Metas de convocatoria'!B46 -> Adulto mayor | C42: ='Metas de convocatoria'!E46 -> 376.29775 | D42: =ROUND(('Metas de convocatoria'!$C$13+(C$17-9*'Metas de convocatoria'!$C$13)*$C42/SUM($C$42:$C$50))/5,0)*5 -> 55 | E42: ='Metas de convocatoria'!G46 -> 65 | F42: =ROUND(('Metas de convocatoria'!$C$13+(E$17-9*'Metas de convocatoria'!$C$13)*$C42/SUM($C$42:$C$50))/5,0)*5 -> 80 | G42: =F42-D42 -> 25 | H42: Piso + reparto proporcional al peso.
A43: Mesas Poblacionales | B43: ='Metas de convocatoria'!B47 -> Infancia | C43: ='Metas de convocatoria'!E47 -> 438.4062 | D43: =ROUND(('Metas de convocatoria'!$C$13+(C$17-9*'Metas de convocatoria'!$C$13)*$C43/SUM($C$42:$C$50))/5,0)*5 -> 55 | E43: ='Metas de convocatoria'!G47 -> 75 | F43: =ROUND(('Metas de convocatoria'!$C$13+(E$17-9*'Metas de convocatoria'!$C$13)*$C43/SUM($C$42:$C$50))/5,0)*5 -> 90 | G43: =F43-D43 -> 35 | H43: Piso + reparto proporcional al peso.
A44: Mesas Poblacionales | B44: ='Metas de convocatoria'!B48 -> LGTBI | C44: ='Metas de convocatoria'!E48 -> 100.49876 | D44: =ROUND(('Metas de convocatoria'!$C$13+(C$17-9*'Metas de convocatoria'!$C$13)*$C44/SUM($C$42:$C$50))/5,0)*5 -> 35 | E44: ='Metas de convocatoria'!G48 -> 40 | F44: =ROUND(('Metas de convocatoria'!$C$13+(E$17-9*'Metas de convocatoria'!$C$13)*$C44/SUM($C$42:$C$50))/5,0)*5 -> 45 | G44: =F44-D44 -> 10 | H44: Piso + reparto proporcional al peso.
A45: Mesas Poblacionales | B45: ='Metas de convocatoria'!B49 -> Discapacidad | C45: ='Metas de convocatoria'!E49 -> 148.1587 | D45: =ROUND(('Metas de convocatoria'!$C$13+(C$17-9*'Metas de convocatoria'!$C$13)*$C45/SUM($C$42:$C$50))/5,0)*5 -> 40 | E45: ='Metas de convocatoria'!G49 -> 45 | F45: =ROUND(('Metas de convocatoria'!$C$13+(E$17-9*'Metas de convocatoria'!$C$13)*$C45/SUM($C$42:$C$50))/5,0)*5 -> 50 | G45: =F45-D45 -> 10 | H45: Piso + reparto proporcional al peso.
A46: Mesas Poblacionales | B46: ='Metas de convocatoria'!B50 -> Juventud | C46: ='Metas de convocatoria'!E50 -> 499.59984 | D46: =ROUND(('Metas de convocatoria'!$C$13+(C$17-9*'Metas de convocatoria'!$C$13)*$C46/SUM($C$42:$C$50))/5,0)*5 -> 60 | E46: ='Metas de convocatoria'!G50 -> 80 | F46: =ROUND(('Metas de convocatoria'!$C$13+(E$17-9*'Metas de convocatoria'!$C$13)*$C46/SUM($C$42:$C$50))/5,0)*5 -> 95 | G46: =F46-D46 -> 35 | H46: Piso + reparto proporcional al peso.
...

Sheet Detalle por mesa
A1: Clasificación | B1: Mesa | C1: Código | D1: Actor / dependencia | E1: Tipo | F1: Sector | G1: Rol en la mesa | H1: Dimensión (condición) en la matriz | I1: Eje transversal Crisis | J1: Aporte en la matriz | K1: Criterio de asignación a la mesa
A2: Mesas Territoriales | B2: Localidad Histórica y del Caribe Norte | C2: Dependencia | D2: Alcaldías Locales 1, 2 y 3 | E2: Territorial | F2: Público | G2: Principal | H2: Comunitaria (Principal); Personal (Secundario) | I2: Secundario | J2: Dependencia distrital ya registrada en la matriz. | K2: Base territorial + Centro Histórico (nombre de la localidad / texto de la matriz) — validar
A3: Mesas Territoriales | B3: Localidad Histórica y del Caribe Norte | C3: Dependencia | D3: Instituto Distrital de Acción Comunal (IDACC) | E3: Descentralizado | F3: Público | G3: Principal | H3: Comunitaria (Principal); Política (Secundario) | I3: — | J3: Dependencia distrital ya registrada en la matriz. | K3: Base territorial + Centro Histórico (nombre de la localidad / texto de la matriz) — validar
A4: Mesas Territoriales | B4: Localidad Histórica y del Caribe Norte | C4: Dependencia | D4: Instituto de Patrimonio y Cultura de Cartagena (IPCC) | E4: Descentralizado | F4: Público | G4: Principal | H4: Comunitaria (Principal); Económica (Secundario) | I4: — | J4: Dependencia distrital ya registrada en la matriz. | K4: Base territorial + Centro Histórico (nombre de la localidad / texto de la matriz) — validar
A5: Mesas Territoriales | B5: Localidad Histórica y del Caribe Norte | C5: Dependencia | D5: Secretaría de Participación y Desarrollo Social (SPD/UMATA) | E5: Secretaría | F5: Público | G5: Principal | H5: Comunitaria (Principal); Económica (Secundario); Alimentaria (Secundario) | I5: — | J5: Dependencia distrital ya registrada en la matriz. | K5: Base territorial + Centro Histórico (nombre de la localidad / texto de la matriz) — validar
A6: Mesas Territoriales | B6: Localidad Histórica y del Caribe Norte | C6: COM-01 | D6: Asociaciones de Juntas de Acción Comunal (ASOJAC) | E6: Comunitario | F6: Social | G6: Principal | H6: Comunitaria (Principal); Política (Secundario) | I6: — | J6: Conocimiento del territorio, convocatoria comunitaria, priorización de problemas. | K6: Base territorial + Centro Histórico (nombre de la localidad / texto de la matriz) — validar
A7: Mesas Territoriales | B7: Localidad Histórica y del Caribe Norte | C7: PRI-03 | D7: Asociación de Comerciantes del Centro Histórico | E7: Sector Privado | F7: Privado | G7: Principal | H7: Económica (Secundario); Personal (Principal) | I7: — | J7: Datos de hurto a comercios, extorsión, percepción de inseguridad. | K7: Base territorial + Centro Histórico (nombre de la localidad / texto de la matriz) — validar
A8: Mesas Territoriales | B8: Localidad Histórica y del Caribe Norte | C8: PRI-08 | D8: Asociación de Dueños de Bares y Discotecas (Centro Histórico) | E8: Sector Privado | F8: Privado | G8: Principal | H8: Comunitaria (Secundario); Personal (Principal) | I8: — | J8: Datos de seguridad en la economía nocturna, convivencia, violencia. | K8: Base territorial + Centro Histórico (nombre de la localidad / texto de la matriz) — validar
A9: Mesas Territoriales | B9: Localidad Histórica y del Caribe Norte | C9: COM-04 | D9: Líderes sociales y comunitarios (barrios en vulnerabilidad) | E9: Comunitario | F9: Social | G9: Principal | H9: Comunitaria (Principal) | I9: — | J9: Conocimiento profundo del territorio, confianza comunitaria, identificación de riesgos. | K9: Base territorial + Centro Histórico (nombre de la localidad / texto de la matriz) — validar
A10: Mesas Territoriales | B10: Localidad Histórica y del Caribe Norte | C10: ACA-11 | D10: Universidad de Bellas Artes | E10: Académico | F10: Social | G10: Principal | H10: Comunitaria (Principal) | I10: — | J10: Investigación, datos, estudios de seguridad. | K10: Base territorial + Centro Histórico (nombre de la localidad / texto de la matriz) — validar
A11: Mesas Territoriales | B11: Localidad Histórica y del Caribe Norte | C11: Dependencia | D11: Gerencia de Espacio Público y Movilidad (GEPM) | E11: Gerencia | F11: Público | G11: Secundario | H11: Comunitaria (Secundario); Económica (Principal); Personal (Secundario) | I11: — | J11: Dependencia distrital ya registrada en la matriz. | K11: Apoyo territorial
A12: Mesas Territoriales | B12: Localidad Histórica y del Caribe Norte | C12: Dependencia | D12: Secretaría de Interior y Convivencia Ciudadana (SICC) | E12: Secretaría | F12: Público | G12: Secundario | H12: Personal (Principal); Política (Secundario) | I12: Secundario | J12: Dependencia distrital ya registrada en la matriz. | K12: Apoyo territorial
... A60: Mesas Rurales | B60: Boquilla | C60: COM-14 | D60: Líderes de corregimientos (Pasacaballos, Bayunca, etc.) | E60: Comunitario | F60: Social | G60: Principal | H60: Comunitaria (Principal); Ambiental (Secundario) | I60: — | J60: Visión rural, acceso a servicios, riesgos ambientales. | K60: Base rural: liderazgo territorial y riesgos ambientales (COM-14/15)
A61: Mesas Rurales | B61: Boquilla | C61: Dependencia | D61: CARDIQUE | E61: Descentralizado | F61: Público | G61: Secundario | H61: Ambiental (Principal) | I61: — | K61: Apoyo ambiental / gestión del riesgo / seguridad marítima
A62: Mesas Rurales | B62: Boquilla | C62: Dependencia | D62: EPA Cartagena | E62: Descentralizado | F62: Público | G62: Secundario | H62: Ambiental (Principal) | I62: — | J62: Dependencia distrital ya registrada en la matriz. | K62: Apoyo ambiental / gestión del riesgo / seguridad marítima
A63: Mesas Rurales | B63: Boquilla | C63: Dependencia | D63: Oficina para la Gestión del Riesgo y Desastres (OAGRD) | E63: Oficina / Unidad asesora | F63: Público | G63: Secundario | H63: Ambiental (Secundario) | I63: Principal | J63: Dependencia distrital ya registrada en la matriz. | K63: Apoyo ambiental / gestión del riesgo / seguridad marítima
A64: Mesas Rurales | B64: Boquilla | C64: Dependencia | D64: Secretaría de Infraestructura | E64: Secretaría | F64: Público | G64: Secundario | H64: Ambiental (Principal); Salud y sanitaria (Secundario) | I64: — | J64: Dependencia distrital ya registrada en la matriz. | K64: Apoyo ambiental / gestión del riesgo / seguridad marítima
A65: Mesas Rurales | B65: Boquilla | C65: FUE-05 | D65: Dirección General Marítima (DIMAR) | E65: Fuerza Pública | F65: Público | G65: Secundario | H65: Ambiental (Principal) | I65: Secundario | J65: Datos sobre seguridad marítima, riesgos costeros, movilidad marítima y protección del territorio marino-costero. | K65: Apoyo ambiental / gestión del riesgo / seguridad marítima
A66: Mesas Rurales | B66: Boquilla | C66: SOC-07 | D66: Fundación Ecovida | E66: Sector Social | F66: Social | G66: Secundario | H66: Comunitaria (Secundario); Ambiental (Principal) | I66: — | J66: Riesgos ambientales, desarrollo sostenible. | K66: Apoyo ambiental / gestión del riesgo / seguridad marítima
A67: Mesas Rurales | B67: Boquilla | C67: FUE-06 | D67: Policía Metropolitana de Cartagena | E67: Fuerza Pública | F67: Público | G67: Secundario | H67: Comunitaria (Secundario); Personal (Principal) | I67: Secundario | J67: Datos de delitos, operativos, mapas de criminalidad, inteligencia e informes sobre los diferentes tipos de violencia en un periodo de los últimos 5 años. | K67: Apoyo ambiental / gestión del riesgo / seguridad marítima
A68: Mesas Rurales | B68: Arroyo de Piedra | C68: Dependencia | D68: Alcaldías Locales 1, 2 y 3 | E68: Territorial | F68: Público | G68: Principal | H68: Comunitaria (Principal); Personal (Secundario) | I68: Secundario | J68: Dependencia distrital ya registrada en la matriz. | K68: Base rural: liderazgo territorial y riesgos ambientales (COM-14/15)
A69: Mesas Rurales | B69: Arroyo de Piedra | C69: Dependencia | D69: Instituto Distrital de Acción Comunal (IDACC) | E69: Descentralizado | F69: Público | G69: Principal | H69: Comunitaria (Principal); Política (Secundario) | I69: — | J69: Dependencia distrital ya registrada en la matriz. | K69: Base rural: liderazgo territorial y riesgos ambientales (COM-14/15)
A70: Mesas Rurales | B70: Arroyo de Piedra | C70: Dependencia | D70: Secretaría de Participación y Desarrollo Social (SPD/UMATA) | E70: Secretaría | F70: Público | G70: Principal | H70: Comunitaria (Principal); Económica (Secundario); Alimentaria (Secundario) | I70: — | J70: Dependencia distrital ya registrada en la matriz. | K70: Base rural: liderazgo territorial y riesgos ambientales (COM-14/15)
A71: Mesas Rurales | B71: Arroyo de Piedra | C71: COM-01 | D71: Asociaciones de Juntas de Acción Comunal (ASOJAC) | E71: Comunitario | F71: Social | G71: Principal | H71: Comunitaria (Principal); Política (Secundario) | I71: — | J71: Conocimiento del territorio, convocatoria comunitaria, priorización de problemas. | K71: Base rural: liderazgo territorial y riesgos ambientales (COM-14/15)
A72: Mesas Rurales | B72: Arroyo de Piedra | C72: COM-14 | D72: Líderes de corregimientos (Pasacaballos, Bayunca, etc.) | E72: Comunitario | F72: Social | G72: Principal | H72: Comunitaria (Principal); Ambiental (Secundario) | I72: — | J72: Visión rural, acceso a servicios, riesgos ambientales. | K72: Base rural: liderazgo territorial y riesgos ambientales (COM-14/15)
A73: Mesas Rurales | B73: Arroyo de Piedra | C73: Dependencia | D73: CARDIQUE | E73: Descentralizado | F73: Público | G73: Secundario | H73: Ambiental (Principal) | I73: — | K73: Apoyo ambiental / gestión del riesgo / seguridad marítima
A74: Mesas Rurales | B74: Arroyo de Piedra | C74: Dependencia | D74: EPA Cartagena | E74: Descentralizado | F74: Público | G74: Secundario | H74: Ambiental (Principal) | I74: — | J74: Dependencia distrital ya registrada en la matriz. | K74: Apoyo ambiental / gestión del riesgo / seguridad marítima
A75: Mesas Rurales | B75: Arroyo de Piedra | C75: Dependencia | D75: Oficina para la Gestión del Riesgo y Desastres (OAGRD) | E75: Oficina / Unidad asesora | F75: Público | G75: Secundario | H75: Ambiental (Secundario) | I75: Principal | J75: Dependencia distrital ya registrada en la matriz. | K75: Apoyo ambiental / gestión del riesgo / seguridad marítima
A76: Mesas Rurales | B76: Arroyo de Piedra | C76: Dependencia | D76: Secretaría de Infraestructura | E76: Secretaría | F76: Público | G76: Secundario | H76: Ambiental (Principal); Salud y sanitaria (Secundario) | I76: — | J76: Dependencia distrital ya registrada en la matriz. | K76: Apoyo ambiental / gestión del riesgo / seguridad marítima
A77: Mesas Rurales | B77: Arroyo de Piedra | C77: FUE-05 | D77: Dirección General Marítima (DIMAR) | E77: Fuerza Pública | F77: Público | G77: Secundario | H77: Ambiental (Principal) | I77: Secundario | J77: Datos sobre seguridad marítima, riesgos costeros, movilidad marítima y protección del territorio marino-costero. | K77: Apoyo ambiental / gestión del riesgo / seguridad marítima
A78: Mesas Rurales | B78: Arroyo de Piedra | C78: SOC-07 | D78: Fundación Ecovida | E78: Sector Social | F78: Social | G78: Secundario | H78: Comunitaria (Secundario); Ambiental (Principal) | I78: — | J78: Riesgos ambientales, desarrollo sostenible. | K78: Apoyo ambiental / gestión del riesgo / seguridad marítima
A79: Mesas Rurales | B79: Arroyo de Piedra | C79: FUE-06 | D79: Policía Metropolitana de Cartagena | E79: Fuerza Pública | F79: Público | G79: Secundario | H79: Comunitaria (Secundario); Personal (Principal) | I79: Secundario | J79: Datos de delitos, operativos, mapas de criminalidad, inteligencia e informes sobre los diferentes tipos de violencia en un periodo de los últimos 5 años. | K79: Apoyo ambiental / gestión del riesgo / seguridad marítima
A80: Mesas Rurales | B80: Punta Canoa | C80: Dependencia | D80: Alcaldías Locales 1, 2 y 3 | E80: Territorial | F80: Público | G80: Principal | H80: Comunitaria (Principal); Personal (Secundario) | I80: Secundario | J80: Dependencia distrital ya registrada en la matriz. | K80: Base rural: liderazgo territorial y riesgos ambientales (COM-14/15)
A81: Mesas Rurales | B81: Punta Canoa | C81: Dependencia | D81: Instituto Distrital de Acción Comunal (IDACC) | E81: Descentralizado | F81: Público | G81: Principal | H81: Comunitaria (Principal); Política (Secundario) | I81: — | J81: Dependencia distrital ya registrada en la matriz. | K81: Base rural: liderazgo territorial y riesgos ambientales (COM-14/15)
